<?xml version="1.0" encoding="utf-8"?>
<!-- This URDF was automatically created by SolidWorks to URDF Exporter! Originally created by Stephen Brawner (brawner@gmail.com) 
     Commit Version: 1.6.0-4-g7f85cfe  Build Version: 1.6.7995.38578
     For more information, please see http://wiki.ros.org/sw_urdf_exporter -->
<robot
  name="self_balancing_robot_urdf">
  <link
    name="base_link">
    <inertial>
      <origin
        xyz="0.000390001845714929 0.0531058768673548 0.000520955534077178"
        rpy="0 0 0" />
      <mass
        value="0.156499785354617" />
      <inertia
        ixx="4.4998860283552E-05"
        ixy="7.3801059384882E-08"
        ixz="-1.0553054171827E-07"
        iyy="0.00013717590508611"
        iyz="-3.01226808255147E-07"
        izz="9.75462410239346E-05" />
    </inertial>
    <visual>
      <origin
        xyz="0 0 0"
        rpy="0 0 0" />
      <geometry>
        <mesh
          filename="package://self_balancing_robot_urdf/meshes/base_link.STL" />
      </geometry>
      <material
        name="">
        <color
          rgba="0.792156862745098 0.819607843137255 0.933333333333333 1" />
      </material>
    </visual>
    <collision>
      <origin
        xyz="0 0 0"
        rpy="0 0 0" />
      <geometry>
        <mesh
          filename="package://self_balancing_robot_urdf/meshes/base_link.STL" />
      </geometry>
    </collision>
  </link>
  <link
    name="link_left_wheel">
    <inertial>
      <origin
        xyz="-1.3686E-05 -7.7641E-06 0.01241"
        rpy="0 0 0" />
      <mass
        value="0.025147" />
      <inertia
        ixx="1.3218E-05"
        ixy="5.9387E-09"
        ixz="-9.5471E-12"
        iyy="1.3211E-05"
        iyz="8.9095E-11"
        izz="2.3884E-05" />
    </inertial>
    <visual>
      <origin
        xyz="0 0 0"
        rpy="0 0 0" />
      <geometry>
        <mesh
          filename="package://self_balancing_robot_urdf/meshes/link_left_wheel.STL" />
      </geometry>
      <material
        name="">
        <color
          rgba="0.29412 0.29412 0.29412 1" />
      </material>
    </visual>
    <collision>
      <origin
        xyz="0 0 0"
        rpy="0 0 0" />
      <geometry>
        <mesh
          filename="package://self_balancing_robot_urdf/meshes/link_left_wheel.STL" />
      </geometry>
    </collision>
  </link>
  <joint
    name="joint_left_wheel"
    type="continuous">
    <origin
      xyz="-0.070108 -0.0015 -0.0165"
      rpy="1.5708 -1.262 -1.5708" />
    <parent
      link="base_link" />
    <child
      link="link_left_wheel" />
    <axis
      xyz="0 0 1" />
  </joint>
  <link
    name="link_right_wheel">
    <inertial>
      <origin
        xyz="-1.3686E-05 7.7641E-06 -0.01241"
        rpy="0 0 0" />
      <mass
        value="0.025147" />
      <inertia
        ixx="1.3218E-05"
        ixy="-5.9387E-09"
        ixz="9.5476E-12"
        iyy="1.3211E-05"
        iyz="8.9096E-11"
        izz="2.3884E-05" />
    </inertial>
    <visual>
      <origin
        xyz="0 0 0"
        rpy="0 0 0" />
      <geometry>
        <mesh
          filename="package://self_balancing_robot_urdf/meshes/link_right_wheel.STL" />
      </geometry>
      <material
        name="">
        <color
          rgba="0.29412 0.29412 0.29412 1" />
      </material>
    </visual>
    <collision>
      <origin
        xyz="0 0 0"
        rpy="0 0 0" />
      <geometry>
        <mesh
          filename="package://self_balancing_robot_urdf/meshes/link_right_wheel.STL" />
      </geometry>
    </collision>
  </link>
  <joint
    name="joint_right_wheel"
    type="fixed">
    <origin
      xyz="0.095 -0.0015 -0.0165"
      rpy="-1.5708 0 -1.5708" />
    <parent
      link="base_link" />
    <child
      link="link_right_wheel" />
    <axis
      xyz="0 0 1" />
  </joint>
</robot>